Workbook

Sheet Capability
A1: Process Capability Study
A2: Yellow cells are inputs. Paste up to 500 individual values in column B (in time order). Green cells are results.
E3: Statistic | F3: Result
A4: LSL | B4: 9.9 | E4: n | F4: =COUNT(B10:B509)
A5: USL | B5: 10.1 | E5: Mean | F5: =AVERAGE(B10:B509)
A6: Target (optional) | B6: 10 | E6: Std dev overall (long term) | F6: =STDEV(B10:B509)
E7: Average moving range | F7: =AVERAGE(C11:C509)
E8: Std dev within (MR-bar / 1.128) | F8: =F7/1.128379
A9: Sample | B9: Value | C9: Moving range | E9: Cp | F9: =(B5-B4)/(6*F8)
A10: 1 | B10: 9.9803 | E10: Cpk | F10: =MIN(B5-F5,F5-B4)/(3*F8)
A11: 2 | B11: 9.9973 | C11: =IF(AND(ISNUMBER(B11),ISNUMBER(B10)),ABS(B11-B10),"") | E11: Cpm | F11: =IF(ISNUMBER(B6),(B5-B4)/(6*SQRT(F8^2+(F5-B6)^2)),"")
A12: 3 | B12: 10.0358 | C12: =IF(AND(ISNUMBER(B12),ISNUMBER(B11)),ABS(B12-B11),"") | E12: Pp | F12: =(B5-B4)/(6*F6)
A13: 4 | B13: 9.9957 | C13: =IF(AND(ISNUMBER(B13),ISNUMBER(B12)),ABS(B13-B12),"") | E13: Ppk | F13: =MIN(B5-F5,F5-B4)/(3*F6)
A14: 5 | B14: 10.0218 | C14: =IF(AND(ISNUMBER(B14),ISNUMBER(B13)),ABS(B14-B13),"") | E14: Expected ppm < LSL (overall) | F14: =NORMSDIST((B4-F5)/F6)*1000000
A15: 6 | B15: 10.0448 | C15: =IF(AND(ISNUMBER(B15),ISNUMBER(B14)),ABS(B15-B14),"") | E15: Expected ppm > USL (overall) | F15: =(1-NORMSDIST((B5-F5)/F6))*1000000
A16: 7 | B16: 10.0343 | C16: =IF(AND(ISNUMBER(B16),ISNUMBER(B15)),ABS(B16-B15),"") | E16: Expected ppm total (overall) | F16: =F14+F15
A17: 8 | B17: 9.998 | C17: =IF(AND(ISNUMBER(B17),ISNUMBER(B16)),ABS(B17-B16),"") | E17: Observed ppm | F17: =(COUNTIF(B10:B509,"<"&B4)+COUNTIF(B10:B509,">"&B5))/F4*1000000
A18: 9 | B18: 10.0231 | C18: =IF(AND(ISNUMBER(B18),ISNUMBER(B17)),ABS(B18-B17),"") | E18: Sigma level (with 1.5 shift) | F18: =NORMSINV(1-F16/1000000)+1.5
A19: 10 | B19: 10.0148 | C19: =IF(AND(ISNUMBER(B19),ISNUMBER(B18)),ABS(B19-B18),"")
A20: 11 | B20: 9.9996 | C20: =IF(AND(ISNUMBER(B20),ISNUMBER(B19)),ABS(B20-B19),"") | E20: Interpretation: Cpk of 1.33 or more is the usual minimum for an existing process; 1.67 for a new or safety-critical one. A big gap between Cpk and Ppk means the process drifts over time.
A21: 12 | B21: 10.0345 | C21: =IF(AND(ISNUMBER(B21),ISNUMBER(B20)),ABS(B21-B20),"")
A22: 13 | B22: 10.0178 | C22: =IF(AND(ISNUMBER(B22),ISNUMBER(B21)),ABS(B22-B21),"")
A23: 14 | B23: 9.986 | C23: =IF(AND(ISNUMBER(B23),ISNUMBER(B22)),ABS(B23-B22),"")
A24: 15 | B24: 9.9782 | C24: =IF(AND(ISNUMBER(B24),ISNUMBER(B23)),ABS(B24-B23),"")
A25: 16 | B25: 10.0019 | C25: =IF(AND(ISNUMBER(B25),ISNUMBER(B24)),ABS(B25-B24),"")
A26: 17 | B26: 10.038 | C26: =IF(AND(ISNUMBER(B26),ISNUMBER(B25)),ABS(B26-B25),"")
A27: 18 | B27: 9.9822 | C27: =IF(AND(ISNUMBER(B27),ISNUMBER(B26)),ABS(B27-B26),"")
A28: 19 | B28: 10.0138 | C28: =IF(AND(ISNUMBER(B28),ISNUMBER(B27)),ABS(B28-B27),"")
A29: 20 | B29: 9.9935 | C29: =IF(AND(ISNUMBER(B29),ISNUMBER(B28)),ABS(B29-B28),"")
A30: 21 | B30: 10.0029 | C30: =IF(AND(ISNUMBER(B30),ISNUMBER(B29)),ABS(B30-B29),"")
A31: 22 | B31: 10.0288 | C31: =IF(AND(ISNUMBER(B31),ISNUMBER(B30)),ABS(B31-B30),"")
A32: 23 | B32: 9.9957 | C32: =IF(AND(ISNUMBER(B32),ISNUMBER(B31)),ABS(B32-B31),"")
... A109: 100 | B109: 10.0359 | C109: =IF(AND(ISNUMBER(B109),ISNUMBER(B108)),ABS(B109-B108),"")
A110: 101 | C110: =IF(AND(ISNUMBER(B110),ISNUMBER(B109)),ABS(B110-B109),"")
A111: 102 | C111: =IF(AND(ISNUMBER(B111),ISNUMBER(B110)),ABS(B111-B110),"")
A112: 103 | C112: =IF(AND(ISNUMBER(B112),ISNUMBER(B111)),ABS(B112-B111),"")
A113: 104 | C113: =IF(AND(ISNUMBER(B113),ISNUMBER(B112)),ABS(B113-B112),"")
A114: 105 | C114: =IF(AND(ISNUMBER(B114),ISNUMBER(B113)),ABS(B114-B113),"")
A115: 106 | C115: =IF(AND(ISNUMBER(B115),ISNUMBER(B114)),ABS(B115-B114),"")
A116: 107 | C116: =IF(AND(ISNUMBER(B116),ISNUMBER(B115)),ABS(B116-B115),"")
...

Sheet I-MR Chart
A1: Individuals and Moving Range Chart
A2: Reads the values on the Capability sheet. The chart shows the first 100 samples; extend the chart ranges for more.
A4: Sample | B4: Value | C4: CL | D4: UCL | E4: LCL | F4: MR | G4: MR-bar | H4: MR UCL | I4: Rule 1
A5: 1 | B5: =IF(ISNUMBER(Capability!B10),Capability!B10,NA()) | C5: =Capability!$F$5 | D5: =Capability!$F$5+3*Capability!$F$8 | E5: =Capability!$F$5-3*Capability!$F$8 | F5: =IF(ISNUMBER(Capability!C10),Capability!C10,NA()) | G5: =Capability!$F$7 | H5: =(1+3*0.8525/1.128379)*Capability!$F$7 | I5: =IF(ISNUMBER(B5),IF(OR(B5>D5,B5<E5),"OUT",""),"")
A6: 2 | B6: =IF(ISNUMBER(Capability!B11),Capability!B11,NA()) | C6: =Capability!$F$5 | D6: =Capability!$F$5+3*Capability!$F$8 | E6: =Capability!$F$5-3*Capability!$F$8 | F6: =IF(ISNUMBER(Capability!C11),Capability!C11,NA()) | G6: =Capability!$F$7 | H6: =(1+3*0.8525/1.128379)*Capability!$F$7 | I6: =IF(ISNUMBER(B6),IF(OR(B6>D6,B6<E6),"OUT",""),"")
A7: 3 | B7: =IF(ISNUMBER(Capability!B12),Capability!B12,NA()) | C7: =Capability!$F$5 | D7: =Capability!$F$5+3*Capability!$F$8 | E7: =Capability!$F$5-3*Capability!$F$8 | F7: =IF(ISNUMBER(Capability!C12),Capability!C12,NA()) | G7: =Capability!$F$7 | H7: =(1+3*0.8525/1.128379)*Capability!$F$7 | I7: =IF(ISNUMBER(B7),IF(OR(B7>D7,B7<E7),"OUT",""),"")
A8: 4 | B8: =IF(ISNUMBER(Capability!B13),Capability!B13,NA()) | C8: =Capability!$F$5 | D8: =Capability!$F$5+3*Capability!$F$8 | E8: =Capability!$F$5-3*Capability!$F$8 | F8: =IF(ISNUMBER(Capability!C13),Capability!C13,NA()) | G8: =Capability!$F$7 | H8: =(1+3*0.8525/1.128379)*Capability!$F$7 | I8: =IF(ISNUMBER(B8),IF(OR(B8>D8,B8<E8),"OUT",""),"")
A9: 5 | B9: =IF(ISNUMBER(Capability!B14),Capability!B14,NA()) | C9: =Capability!$F$5 | D9: =Capability!$F$5+3*Capability!$F$8 | E9: =Capability!$F$5-3*Capability!$F$8 | F9: =IF(ISNUMBER(Capability!C14),Capability!C14,NA()) | G9: =Capability!$F$7 | H9: =(1+3*0.8525/1.128379)*Capability!$F$7 | I9: =IF(ISNUMBER(B9),IF(OR(B9>D9,B9<E9),"OUT",""),"")
A10: 6 | B10: =IF(ISNUMBER(Capability!B15),Capability!B15,NA()) | C10: =Capability!$F$5 | D10: =Capability!$F$5+3*Capability!$F$8 | E10: =Capability!$F$5-3*Capability!$F$8 | F10: =IF(ISNUMBER(Capability!C15),Capability!C15,NA()) | G10: =Capability!$F$7 | H10: =(1+3*0.8525/1.128379)*Capability!$F$7 | I10: =IF(ISNUMBER(B10),IF(OR(B10>D10,B10<E10),"OUT",""),"")
A11: 7 | B11: =IF(ISNUMBER(Capability!B16),Capability!B16,NA()) | C11: =Capability!$F$5 | D11: =Capability!$F$5+3*Capability!$F$8 | E11: =Capability!$F$5-3*Capability!$F$8 | F11: =IF(ISNUMBER(Capability!C16),Capability!C16,NA()) | G11: =Capability!$F$7 | H11: =(1+3*0.8525/1.128379)*Capability!$F$7 | I11: =IF(ISNUMBER(B11),IF(OR(B11>D11,B11<E11),"OUT",""),"")
A12: 8 | B12: =IF(ISNUMBER(Capability!B17),Capability!B17,NA()) | C12: =Capability!$F$5 | D12: =Capability!$F$5+3*Capability!$F$8 | E12: =Capability!$F$5-3*Capability!$F$8 | F12: =IF(ISNUMBER(Capability!C17),Capability!C17,NA()) | G12: =Capability!$F$7 | H12: =(1+3*0.8525/1.128379)*Capability!$F$7 | I12: =IF(ISNUMBER(B12),IF(OR(B12>D12,B12<E12),"OUT",""),"")
A13: 9 | B13: =IF(ISNUMBER(Capability!B18),Capability!B18,NA()) | C13: =Capability!$F$5 | D13: =Capability!$F$5+3*Capability!$F$8 | E13: =Capability!$F$5-3*Capability!$F$8 | F13: =IF(ISNUMBER(Capability!C18),Capability!C18,NA()) | G13: =Capability!$F$7 | H13: =(1+3*0.8525/1.128379)*Capability!$F$7 | I13: =IF(ISNUMBER(B13),IF(OR(B13>D13,B13<E13),"OUT",""),"")
A14: 10 | B14: =IF(ISNUMBER(Capability!B19),Capability!B19,NA()) | C14: =Capability!$F$5 | D14: =Capability!$F$5+3*Capability!$F$8 | E14: =Capability!$F$5-3*Capability!$F$8 | F14: =IF(ISNUMBER(Capability!C19),Capability!C19,NA()) | G14: =Capability!$F$7 | H14: =(1+3*0.8525/1.128379)*Capability!$F$7 | I14: =IF(ISNUMBER(B14),IF(OR(B14>D14,B14<E14),"OUT",""),"")
A15: 11 | B15: =IF(ISNUMBER(Capability!B20),Capability!B20,NA()) | C15: =Capability!$F$5 | D15: =Capability!$F$5+3*Capability!$F$8 | E15: =Capability!$F$5-3*Capability!$F$8 | F15: =IF(ISNUMBER(Capability!C20),Capability!C20,NA()) | G15: =Capability!$F$7 | H15: =(1+3*0.8525/1.128379)*Capability!$F$7 | I15: =IF(ISNUMBER(B15),IF(OR(B15>D15,B15<E15),"OUT",""),"")
A16: 12 | B16: =IF(ISNUMBER(Capability!B21),Capability!B21,NA()) | C16: =Capability!$F$5 | D16: =Capability!$F$5+3*Capability!$F$8 | E16: =Capability!$F$5-3*Capability!$F$8 | F16: =IF(ISNUMBER(Capability!C21),Capability!C21,NA()) | G16: =Capability!$F$7 | H16: =(1+3*0.8525/1.128379)*Capability!$F$7 | I16: =IF(ISNUMBER(B16),IF(OR(B16>D16,B16<E16),"OUT",""),"")
... A504: 500 | B504: =IF(ISNUMBER(Capability!B509),Capability!B509,NA()) | C504: =Capability!$F$5 | D504: =Capability!$F$5+3*Capability!$F$8 | E504: =Capability!$F$5-3*Capability!$F$8 | F504: =IF(ISNUMBER(Capability!C509),Capability!C509,NA()) | G504: =Capability!$F$7 | H504: =(1+3*0.8525/1.128379)*Capability!$F$7 | I504: =IF(ISNUMBER(B504),IF(OR(B504>D504,B504<E504),"OUT",""),"")
